Workbook

Sheet Cover
A1: HOME FINANCE PLANNING WORKBOOK
A2: Loan affordability, repayment, investment growth, and a practical roadmap for the wider financial journey
A4: CONTENTS | B4: PURPOSE | C4: REVIEW STATUS
A5: Rent vs Buy | B5: Compares purchasing a home with renting and investing the avoided down payment and monthly savings. | C5: Reviewed by Ashwani
A6: Home Loan Analysis | B6: Evaluates home ownership against SIP investing under common long-term assumptions. | C6: Reviewed by Ashwani
A7: EMI Calculator | B7: Calculates EMI and provides a yearly principal-and-interest repayment schedule. | C7: Reviewed by Ashwani
A8: SIP Growth | B8: Projects yearly SIP growth, tax, inflation-adjusted value, and model assumptions. | C8: Reviewed by Ashwani
A9: Expense Ratio Impact | B9: Compares direct and regular mutual fund expense ratios and shows the long-term rupee cost over 5–30 years. | C9: Reviewed by Ashwani
A10: Loan Prepayment | B10: Models normal repayment, five lump sums, monthly extra payments, rate changes, and a combined scenario. | C10: Pending manual review
A11: Step-Up SIP Goal | B11: Calculates the starting SIP and annual step-up needed for an inflation-adjusted future goal after simplified tax. | C11: Pending manual review
A12: Retirement SWP | B12: Calculates the retirement corpus required, tests the current saving path, and models inflation-linked withdrawals for up to 40 years. | C12: Pending manual review
A13: Emergency Fund | B13: Builds a risk-adjusted emergency target from essential expenses and projects the month-by-month funding path. | C13: Pending manual review
A14: Net Worth & Cash Flow | B14: Tracks household net worth, savings rate, debt burden, liquidity, and monthly goal capacity. | C14: Pending manual review
A15: Term Insurance | B15: Estimates family protection from income replacement, loans, future goals, available assets, and existing cover. | C15: Pending manual review
... A18: Prepay vs Invest | B18: Compares investing surplus with two loan-prepayment strategies using post-tax wealth, risk, and liquidity. | C18: Pending manual review
A19: RECOMMENDED CALCULATOR ROADMAP
A20: Priority | B20: Calculator to create | C20: What it should answer
A21: 1 — Built | B21: Mutual Fund Expense-Ratio Impact | C21: How much wealth is lost over time because of fund expenses? Compare two expense ratios, direct vs regular plans, and show the rupee cost after 5–30 years.
A22: 2 — Built | B22: Home-Loan Part-Payment & Prepayment | C22: How much interest and tenure can be saved with one-time or annual prepayments? Choose Reduce EMI or Reduce Tenure and compare the outcome.
A23: 3 — Built | B23: Step-Up SIP Goal Planner | C23: What starting SIP and annual increase are needed for a future goal after inflation and simplified tax? Includes a 30-year funding schedule.
A24: 4 — Built | B24: Prepay Loan vs Invest | C24: Should surplus cash be used to prepay the loan or invested? Compare guaranteed interest savings with uncertain post-tax investment returns.
A25: 5 — Built | B25: Retirement Corpus & SWP | C25: How large a retirement corpus is required, and how long could it last under inflation, returns, taxes, and monthly withdrawals?
A26: 6 — Built | B26: Emergency-Fund Calculator | C26: How many months of essential expenses should be held, and how long will it take to build the target?
A27: 7 — Built | B27: Net-Worth & Monthly Cash-Flow Tracker | C27: What is the household’s current net worth, savings rate, debt burden, and monthly surplus available for goals?
A28: 8 — Built | B28: Term-Insurance Need Calculator | C28: How much life cover may be needed after considering dependants, debts, future goals, existing assets, and current insurance?
A29: 9 — Built | B29: Asset-Allocation & Rebalancing Tool | C29: What equity, debt, gold, and cash mix matches the goal horizon and risk comfort, and what trades restore the target allocation?
A30: 10 — Built | B30: Goal-Based Investment Dashboard | C30: Track several goals together, show funded percentage, monthly gap, required SIP, and priority when cash is limited.
A32: ARTICLE & LEARNING ROADMAP
A33: Status / journey stage | B33: Article to write | C33: Simple-language focus
A34: Covered in calculator — Safety | B34: How to Build an Emergency Fund | C34: What counts as an emergency, where to keep the money, and why emergency savings come before aggressive investing.
A35: Pending — Start here | B35: Needs, Wants, Savings and Debt | C35: A simple monthly-money system, savings rate, debt priorities, and how to avoid investing money needed soon.
A36: Covered in calculator — Mutual funds | B36: How Expense Ratio Quietly Reduces Wealth | C36: Explain TER, daily NAV deduction, compounding drag, and why a small annual percentage can create a large long-term rupee difference.
A37: Pending — Mutual funds | B37: How to Choose a Mutual Fund Without Technical Jargon | C37: Start with the goal and horizon, select a suitable category, check the SEBI Riskometer, understand costs, compare consistency, and avoid chasing last year’s winner.
A38: Pending — Mutual funds | B38: Direct vs Regular Mutual Funds | C38: Same portfolio but different costs and support: who may prefer DIY direct plans and who may value professional guidance.
A39: Covered in calculators — Mutual funds | B39: SIP, Lumpsum and Step-Up SIP | C39: When each method may fit, how cash-flow timing changes results, and why discipline matters more than predicting the market.
A40: Covered in calculator — Home loans | B40: How Part-Payment Reduces Home-Loan Interest | C40: Why early prepayments save more interest, the difference between reducing EMI and tenure, and what to confirm with the lender.
A41: Pending — Home loans | B41: Prepay Loan or Invest Surplus? A Decision Framework | C41: Compare certainty, liquidity, tax, risk, return assumptions, and the emotional benefit of becoming debt-free.
A42: Built article — Retirement | B42: Nominal Wealth vs Real Wealth | C42: Show why inflation changes purchasing power and why retirement and long-term goals must be planned in today’s rupees.
A43: Pending — Retirement | B43: Sequence-of-Returns Risk in Retirement | C43: Explain why poor returns early in retirement can be damaging even when the long-term average return looks acceptable.
A44: Pending — Protection | B44: Term Insurance and Health Insurance Basics | C44: Explain what each policy protects, common exclusions, adequate cover, and why insurance is not an investment return product.
...

Sheet Common Assumptions
A1: COMMON ASSUMPTIONS — MODEL CONTROL
A2: Edit the blue cells only. Linked calculators update automatically; scenario-specific exceptions are listed below.
A4: PARAMETER | B4: DEFAULT | C4: UNIT | D4: APPLIES TO
A5: General inflation | B5: 6 | C5: % p.a. | D5: Real-value and future-cost calculations
A6: Illustrative investment return | B6: 12 | C6: % p.a. | D6: Long-term SIP / equity illustrations
A7: Home / general loan rate | B7: 7.5 | C7: % p.a. | D7: Home-loan and loan-comparison calculators
A8: Property appreciation | B8: 10 | C8: % p.a. | D8: Property comparison models
A9: Property maintenance | B9: 1 | C9: % p.a. | D9: Property comparison models
A10: Direct-plan / investment cost | B10: 0.5 | C10: % p.a. | D10: Investment cost assumptions
A11: Regular-plan expense ratio | B11: 1.5 | C11: % p.a. | D11: Expense-ratio comparison only
A12: LTCG tax rate | B12: 12.5 | C12: % | D12: Simplified investment tax illustrations
A13: LTCG exemption | B13: 125000 | C13: ₹ | D13: Simplified investment tax illustrations
A14: Annual rent increase | B14: 10 | C14: % p.a. | D14: Rent vs Buy only
A15: Annual SIP step-up | B15: 10 | C15: % p.a. | D15: Step-Up SIP Goal only
A16: Post-retirement gross return | B16: 8 | C16: % p.a. | D16: Retirement withdrawal phase only
A17: Liquid savings return | B17: 4 | C17: % p.a. | D17: Emergency-fund savings only
A19: SCENARIO-SPECIFIC EXCEPTIONS
A20: Loan reset rate | B20: Linked to common loan rate by default | D20: Overwrite only to test a lender reset scenario
A21: Goal-level return | B21: 12% for ordinary goals; 4% for emergency fund | D21: Separates long-term investment from liquid savings
A22: Post-retirement tax/cost drag | B22: Kept in scenario sheet | D22: Distinct from pre-retirement investment cost
A23: LTV loan-size threshold 1 | B23: 3000000 | C23: ₹ loan amount | D23: Home Loan Analysis; Rent vs Buy — RBI Master Circular – Housing Finance (rbi.org.in)
A24: LTV loan-size threshold 2 | B24: 7500000 | C24: ₹ loan amount | D24: Home Loan Analysis; Rent vs Buy — RBI Master Circular – Housing Finance (rbi.org.in)
A25: Maximum LTV — band 1 | B25: 90 | C25: % | D25: Home Loan Analysis; Rent vs Buy — RBI Master Circular – Housing Finance (rbi.org.in)
A26: Maximum LTV — band 2 | B26: 80 | C26: % | D26: Home Loan Analysis; Rent vs Buy — RBI Master Circular – Housing Finance (rbi.org.in)
A27: Maximum LTV — band 3 | B27: 75 | C27: % | D27: Home Loan Analysis; Rent vs Buy — RBI Master Circular – Housing Finance (rbi.org.in)
A28: Tax rate on property sale gain | B28: 12.5 | C28: % | D28: Property comparisons — Income Tax Department capital gains page; applies to property bought on or after 23 July 2024
A29: Selling cost | B29: 0 | C29: % of sale value | D29: Property comparisons

Sheet Rent vs Buy
A1: RENT VS BUY — LONG-TERM WEALTH COMPARISON
A2: Buying means living in the ready-possession home and repaying the loan over the selected tenure; renting means investing the avoided down payment plus EMI and maintenance saved after paying rent.
A4: MODEL INPUTS | D4: DECISION SUMMARY | G4: HOW TO READ THE RESULT | M4: RETURN SENSITIVITY
A5: Property Price (₹) | B5: 10000000 | D5: Monthly EMI | E5: =-PMT($B$7/1200,$B$8*12,$B$6) -> 60419.49 | G5: ="1. After "&TEXT($B$8,"0")&" years, buying creates real net wealth of ₹"&TEXT($E$9,"##,##,##0")&" versus ₹"&TEXT($E$10,"##,##,##0")&" from renting and investing." -> 1. After 20 years, buying creates real net wealth of ₹1,87,44,336 versus ₹1,26,30,239 from renting and investing. | M5: Return | N5: Leader | O5: Lead (Real)
A6: Loan Amount (₹) | B6: 7500000 | D6: First-Year Maintenance | E6: =$B$5*$B$9/100 -> 100000 | G6: ="2. "&IF($E$11>=0,"Buying leads by ₹","Renting and investing leads by ₹")&TEXT(ABS($E$11),"##,##,##0")&" in today’s rupees under the selected assumptions." -> 2. Buying leads by ₹61,14,097 in today’s rupees under the selected assumptions. | M6: 8 | N6: =IF('Rent Buy Sensitivity'!L21>=0,"Buy","Rent + Invest") -> Buy | O6: =ABS('Rent Buy Sensitivity'!L21) -> 13253943
A7: Loan Interest (% p.a.) | B7: ='Common Assumptions'!$B$7 -> 7.5 | D7: Buyer Total Cash Outlay | E7: =$B$5-$B$6+$E$5*$B$8*12+$E$6*$B$8 -> 19000677 | G7: ="3. The renter starts by investing the avoided down payment of ₹"&TEXT($B$5-$B$6,"##,##,##0")&" and then invests EMI plus maintenance less rent each month." -> 3. The renter starts by investing the avoided down payment of ₹25,00,000 and then invests EMI plus maintenance less rent each month. | M7: 10 | N7: =IF('Rent Buy Sensitivity'!L41>=0,"Buy","Rent + Invest") -> Buy | O7: =ABS('Rent Buy Sensitivity'!L41) -> 10347581
A8: Tenure (years) | B8: 20 | D8: Total Rent Paid | E8: =$B$13*12*IF($B$14=0,$B$8,((1+$B$14/100)^$B$8-1)/($B$14/100)) -> 17182500 | G8: ="4. Starting rent is ₹"&TEXT($B$13,"##,##,##0")&" per month, rising "&TEXT($B$14/100,"0.0%")&" yearly; investment returns are assumed at "&TEXT($B$12/100,"0.0%")&" nominally." -> 4. Starting rent is ₹25,000 per month, rising 10.0% yearly; investment returns are assumed at 12.0% nominally. | M8: 12 | N8: =IF('Rent Buy Sensitivity'!L61>=0,"Buy","Rent + Invest") -> Buy | O8: =ABS('Rent Buy Sensitivity'!L61) -> 6114096.8
A9: Maintenance (% p.a.) | B9: ='Common Assumptions'!$B$9 -> 1 | D9: Buy Net Wealth (Real) | E9: {=INDEX($H$21:$H$40,$B$8)} -> 18744336 | M9: 14 | N9: =IF('Rent Buy Sensitivity'!L81>=0,"Buy","Rent + Invest") -> Rent + Invest | O9: =ABS('Rent Buy Sensitivity'!L81) -> 47883.548
A10: Property Appreciation (% p.a.) | B10: ='Common Assumptions'!$B$8 -> 10 | D10: Rent + Invest Wealth (Real) | E10: {=INDEX($K$21:$K$40,$B$8)} -> 12630239 | G10: KEY ASSUMPTIONS & LIMITATIONS | M10: 16 | N10: =IF('Rent Buy Sensitivity'!L101>=0,"Buy","Rent + Invest") -> Rent + Invest | O10: =ABS('Rent Buy Sensitivity'!L101) -> 9013194.6
A11: Inflation (% p.a.) | B11: ='Common Assumptions'!$B$5 -> 6 | D11: Buy Advantage / (Rent Advantage) | E11: =E9-E10 -> 6114096.8 | G11: 1. Buyer wealth equals property value less outstanding loan; both are inflation-adjusted for the real comparison.
A12: Illustrative Investment Return (% p.a.) | B12: ='Common Assumptions'!$B$6 -> 12 | D12: Current Decision | E12: =IF(E11>=0,"BUY LEADS","RENT + INVEST LEADS") -> BUY LEADS | G12: 2. The buyer pays EMI and flat annual maintenance. The renter invests the monthly difference; if rent exceeds ownership cost, the model treats the difference as a portfolio withdrawal. | M12: Illustrative scenarios, not forecasts or guarantees. All other inputs remain unchanged.
A13: Starting Monthly Rent (₹) | B13: 25000 | G13: 3. Renter tax assumes a full year-end redemption and qualifying Section 112A LTCG above the exemption. Recent SIP instalments, cess, surcharge, and tax harvesting are excluded.
A14: Annual Rent Increase (%) | B14: ='Common Assumptions'!$B$14 -> 10 | G14: 4. Stamp duty, registration, property tax, insurance, loan tax benefits, rent deposits, moving costs, investment fees, and liquidity or risk differences are excluded. Selling cost and sale-gain tax use the shared illustrative assumptions.
A15: LTCG Tax Rate (%) | B15: ='Common Assumptions'!$B$12 -> 12.5 | G15: 5. Returns, appreciation, inflation, rent escalation, and interest rates are constant assumptions—not forecasts or guarantees.
A16: LTCG Exemption (₹) | B16: ='Common Assumptions'!$B$13 -> 125000 | G16: 6. Net contributions after any modeled withdrawals are used as a simplified tax cost basis; actual tax-lot calculations may differ.
A17: Loan-to-Value Ratio | B17: =$B$6/$B$5 -> 0.75 | D17: LTV Check | E17: =IF(OR('Common Assumptions'!$B$23="",'Common Assumptions'!$B$24="",'Common Assumptions'!$B$25="",'Common Assumptions'!$B$26="",'Common Assumptions'!$B$27=""),"",IF(B17>IF($B$6<='Common Assumptions'!$B$23,'Common Assumptions'!$B$25/100,IF($B$6<='Common Assumptions'!$B$24,'Common Assumptions'!$B$26/100,'Common Assumptions'!$B$27/100)),"Above regulatory LTV limit for this loan size: verify with your lender","Within configured LTV limit")) -> Within configured LTV limit
A19: YEARLY RENT VS BUY WEALTH SCHEDULE
A20: Year | B20: Annual Rent | C20: Monthly Invest Difference | D20: Renter Net Contributions | E20: Property Value | F20: Loan Balance | G20: Buy Net Wealth | H20: Buy Net Wealth (Real) | I20: Renter Portfolio | J20: Estimated Tax | K20: Renter Post-Tax Wealth (Real)
A21: =1 -> 1 | B21: =$B$13*12*(1+$B$14/100)^(A21-1) -> 300000 | C21: =$E$5+$E$6/12-$B$13*(1+$B$14/100)^(A21-1) -> 43752.823 | D21: =$B$5-$B$6+C21*12 -> 3025033.9 | E21: =$B$5*(1+$B$10/100)^A21 -> 11000000 | F21: =IF(A21>=$B$8,0,MAX(0,-FV($B$7/1200,A21*12,-$E$5,$B$6))) -> 7331761 | G21: =E21-E21*'Common Assumptions'!$B$29/100-MAX(0,E21-$B$5-E21*'Common Assumptions'!$B$29/100)*'Common Assumptions'!$B$28/100-F21 -> 3543239 | H21: =G21/(1+$B$11/100)^A21 -> 3342678.3 | I21: =($B$5-$B$6)*(1+$B$12/1200)^12+FV($B$12/1200,12,-C21,0,0) -> 3371957.9 | J21: =MAX(0,I21-D21-$B$16)*$B$15/100 -> 27740.501 | K21: =(I21-J21)/(1+$B$11/100)^A21 -> 3154922.1
A22: =A21+1 -> 2 | B22: =$B$13*12*(1+$B$14/100)^(A22-1) -> 330000 | C22: =$E$5+$E$6/12-$B$13*(1+$B$14/100)^(A22-1) -> 41252.823 | D22: =D21+C22*12 -> 3520067.7 | E22: =$B$5*(1+$B$10/100)^A22 -> 12100000 | F22: =IF(A22>=$B$8,0,MAX(0,-FV($B$7/1200,A22*12,-$E$5,$B$6))) -> 7150461.1 | G22: =E22-E22*'Common Assumptions'!$B$29/100-MAX(0,E22-$B$5-E22*'Common Assumptions'!$B$29/100)*'Common Assumptions'!$B$28/100-F22 -> 4687038.9 | H22: =G22/(1+$B$11/100)^A22 -> 4171447.9 | I22: =I21*(1+$B$12/1200)^12+FV($B$12/1200,12,-C22,0,0) -> 4322795.6 | J22: =MAX(0,I22-D22-$B$16)*$B$15/100 -> 84715.981 | K22: =(I22-J22)/(1+$B$11/100)^A22 -> 3771875.8
A23: =A22+1 -> 3 | B23: =$B$13*12*(1+$B$14/100)^(A23-1) -> 363000 | C23: =$E$5+$E$6/12-$B$13*(1+$B$14/100)^(A23-1) -> 38502.823 | D23: =D22+C23*12 -> 3982101.6 | E23: =$B$5*(1+$B$10/100)^A23 -> 13310000 | F23: =IF(A23>=$B$8,0,MAX(0,-FV($B$7/1200,A23*12,-$E$5,$B$6))) -> 6955086.5 | G23: =E23-E23*'Common Assumptions'!$B$29/100-MAX(0,E23-$B$5-E23*'Common Assumptions'!$B$29/100)*'Common Assumptions'!$B$28/100-F23 -> 5941163.5 | H23: =G23/(1+$B$11/100)^A23 -> 4988315.5 | I23: =I22*(1+$B$12/1200)^12+FV($B$12/1200,12,-C23,0,0) -> 5359346.4 | J23: =MAX(0,I23-D23-$B$16)*$B$15/100 -> 156530.6 | K23: =(I23-J23)/(1+$B$11/100)^A23 -> 4368384.5
A24: =A23+1 -> 4 | B24: =$B$13*12*(1+$B$14/100)^(A24-1) -> 399300 | C24: =$E$5+$E$6/12-$B$13*(1+$B$14/100)^(A24-1) -> 35477.823 | D24: =D23+C24*12 -> 4407835.5 | E24: =$B$5*(1+$B$10/100)^A24 -> 14641000 | F24: =IF(A24>=$B$8,0,MAX(0,-FV($B$7/1200,A24*12,-$E$5,$B$6))) -> 6744544.4 | G24: =E24-E24*'Common Assumptions'!$B$29/100-MAX(0,E24-$B$5-E24*'Common Assumptions'!$B$29/100)*'Common Assumptions'!$B$28/100-F24 -> 7316330.6 | H24: =G24/(1+$B$11/100)^A24 -> 5795219.1 | I24: =I23*(1+$B$12/1200)^12+FV($B$12/1200,12,-C24,0,0) -> 6488993.3 | J24: =MAX(0,I24-D24-$B$16)*$B$15/100 -> 244519.73 | K24: =(I24-J24)/(1+$B$11/100)^A24 -> 4946208
A25: =A24+1 -> 5 | B25: =$B$13*12*(1+$B$14/100)^(A25-1) -> 439230 | C25: =$E$5+$E$6/12-$B$13*(1+$B$14/100)^(A25-1) -> 32150.323 | D25: =D24+C25*12 -> 4793639.4 | E25: =$B$5*(1+$B$10/100)^A25 -> 16105100 | F25: =IF(A25>=$B$8,0,MAX(0,-FV($B$7/1200,A25*12,-$E$5,$B$6))) -> 6517657.4 | G25: =E25-E25*'Common Assumptions'!$B$29/100-MAX(0,E25-$B$5-E25*'Common Assumptions'!$B$29/100)*'Common Assumptions'!$B$28/100-F25 -> 8824305.1 | H25: =G25/(1+$B$11/100)^A25 -> 6594034.1 | I25: =I24*(1+$B$12/1200)^12+FV($B$12/1200,12,-C25,0,0) -> 7719706.6 | J25: =MAX(0,I25-D25-$B$16)*$B$15/100 -> 350133.41 | K25: =(I25-J25)/(1+$B$11/100)^A25 -> 5506973.8
A26: =A25+1 -> 6 | B26: =$B$13*12*(1+$B$14/100)^(A26-1) -> 483153 | C26: =$E$5+$E$6/12-$B$13*(1+$B$14/100)^(A26-1) -> 28490.073 | D26: =D25+C26*12 -> 5135520.2 | E26: =$B$5*(1+$B$10/100)^A26 -> 17715610 | F26: =IF(A26>=$B$8,0,MAX(0,-FV($B$7/1200,A26*12,-$E$5,$B$6))) -> 6273156.5 | G26: =E26-E26*'Common Assumptions'!$B$29/100-MAX(0,E26-$B$5-E26*'Common Assumptions'!$B$29/100)*'Common Assumptions'!$B$28/100-F26 -> 10478002 | H26: =G26/(1+$B$11/100)^A26 -> 7386578.1 | I26: =I25*(1+$B$12/1200)^12+FV($B$12/1200,12,-C26,0,0) -> 9060084.1 | J26: =MAX(0,I26-D26-$B$16)*$B$15/100 -> 474945.48 | K26: =(I26-J26)/(1+$B$11/100)^A26 -> 6052184
A27: =A26+1 -> 7 | B27: =$B$13*12*(1+$B$14/100)^(A27-1) -> 531468.3 | C27: =$E$5+$E$6/12-$B$13*(1+$B$14/100)^(A27-1) -> 24463.798 | D27: =D26+C27*12 -> 5429085.8 | E27: =$B$5*(1+$B$10/100)^A27 -> 19487171 | F27: =IF(A27>=$B$8,0,MAX(0,-FV($B$7/1200,A27*12,-$E$5,$B$6))) -> 6009674.5 | G27: =E27-E27*'Common Assumptions'!$B$29/100-MAX(0,E27-$B$5-E27*'Common Assumptions'!$B$29/100)*'Common Assumptions'!$B$28/100-F27 -> 12291600 | H27: =G27/(1+$B$11/100)^A27 -> 8174616.1 | I27: =I26*(1+$B$12/1200)^12+FV($B$12/1200,12,-C27,0,0) -> 10519392 | J27: =MAX(0,I27-D27-$B$16)*$B$15/100 -> 620663.24 | K27: =(I27-J27)/(1+$B$11/100)^A27 -> 6583219.8
A28: =A27+1 -> 8 | B28: =$B$13*12*(1+$B$14/100)^(A28-1) -> 584615.13 | C28: =$E$5+$E$6/12-$B$13*(1+$B$14/100)^(A28-1) -> 20034.895 | D28: =D27+C28*12 -> 5669504.6 | E28: =$B$5*(1+$B$10/100)^A28 -> 21435888 | F28: =IF(A28>=$B$8,0,MAX(0,-FV($B$7/1200,A28*12,-$E$5,$B$6))) -> 5725737.6 | G28: =E28-E28*'Common Assumptions'!$B$29/100-MAX(0,E28-$B$5-E28*'Common Assumptions'!$B$29/100)*'Common Assumptions'!$B$28/100-F28 -> 14280664 | H28: =G28/(1+$B$11/100)^A28 -> 8959865.6 | I28: =I27*(1+$B$12/1200)^12+FV($B$12/1200,12,-C28,0,0) -> 12107607 | J28: =MAX(0,I28-D28-$B$16)*$B$15/100 -> 789137.75 | K28: =(I28-J28)/(1+$B$11/100)^A28 -> 7101347.3
A29: =A28+1 -> 9 | B29: =$B$13*12*(1+$B$14/100)^(A29-1) -> 643076.64 | C29: =$E$5+$E$6/12-$B$13*(1+$B$14/100)^(A29-1) -> 15163.103 | D29: =D28+C29*12 -> 5851461.8 | E29: =$B$5*(1+$B$10/100)^A29 -> 23579477 | F29: =IF(A29>=$B$8,0,MAX(0,-FV($B$7/1200,A29*12,-$E$5,$B$6))) -> 5419758 | G29: =E29-E29*'Common Assumptions'!$B$29/100-MAX(0,E29-$B$5-E29*'Common Assumptions'!$B$29/100)*'Common Assumptions'!$B$28/100-F29 -> 16462284 | H29: =G29/(1+$B$11/100)^A29 -> 9744000.8 | I29: =I28*(1+$B$12/1200)^12+FV($B$12/1200,12,-C29,0,0) -> 13835460 | J29: =MAX(0,I29-D29-$B$16)*$B$15/100 -> 982374.8 | K29: =(I29-J29)/(1+$B$11/100)^A29 -> 7607721.5
A30: =A29+1 -> 10 | B30: =$B$13*12*(1+$B$14/100)^(A30-1) -> 707384.31 | C30: =$E$5+$E$6/12-$B$13*(1+$B$14/100)^(A30-1) -> 9804.1306 | D30: =D29+C30*12 -> 5969111.4 | E30: =$B$5*(1+$B$10/100)^A30 -> 25937425 | F30: =IF(A30>=$B$8,0,MAX(0,-FV($B$7/1200,A30*12,-$E$5,$B$6))) -> 5090024.3 | G30: =E30-E30*'Common Assumptions'!$B$29/100-MAX(0,E30-$B$5-E30*'Common Assumptions'!$B$29/100)*'Common Assumptions'!$B$28/100-F30 -> 18855222 | H30: =G30/(1+$B$11/100)^A30 -> 10528658 | I30: =I29*(1+$B$12/1200)^12+FV($B$12/1200,12,-C30,0,0) -> 15714484 | J30: =MAX(0,I30-D30-$B$16)*$B$15/100 -> 1202546.6 | K30: =(I30-J30)/(1+$B$11/100)^A30 -> 8103389.9
A31: =A30+1 -> 11 | B31: =$B$13*12*(1+$B$14/100)^(A31-1) -> 778122.74 | C31: =$E$5+$E$6/12-$B$13*(1+$B$14/100)^(A31-1) -> 3909.2613 | D31: =D30+C31*12 -> 6016022.5 | E31: =$B$5*(1+$B$10/100)^A31 -> 28531167 | F31: =IF(A31>=$B$8,0,MAX(0,-FV($B$7/1200,A31*12,-$E$5,$B$6))) -> 4734692.6 | G31: =E31-E31*'Common Assumptions'!$B$29/100-MAX(0,E31-$B$5-E31*'Common Assumptions'!$B$29/100)*'Common Assumptions'!$B$28/100-F31 -> 21480079 | H31: =G31/(1+$B$11/100)^A31 -> 11315437 | I31: =I30*(1+$B$12/1200)^12+FV($B$12/1200,12,-C31,0,0) -> 17757053 | J31: =MAX(0,I31-D31-$B$16)*$B$15/100 -> 1452003.8 | K31: =(I31-J31)/(1+$B$11/100)^A31 -> 8589296.5
A32: =A31+1 -> 12 | B32: =$B$13*12*(1+$B$14/100)^(A32-1) -> 855935.01 | C32: =$E$5+$E$6/12-$B$13*(1+$B$14/100)^(A32-1) -> -2575.0948 | D32: =D31+C32*12 -> 5985121.4 | E32: =$B$5*(1+$B$10/100)^A32 -> 31384284 | F32: =IF(A32>=$B$8,0,MAX(0,-FV($B$7/1200,A32*12,-$E$5,$B$6))) -> 4351775.6 | G32: =E32-E32*'Common Assumptions'!$B$29/100-MAX(0,E32-$B$5-E32*'Common Assumptions'!$B$29/100)*'Common Assumptions'!$B$28/100-F32 -> 24359473 | H32: =G32/(1+$B$11/100)^A32 -> 12105912 | I32: =I31*(1+$B$12/1200)^12+FV($B$12/1200,12,-C32,0,0) -> 19976433 | J32: =MAX(0,I32-D32-$B$16)*$B$15/100 -> 1733289 | K32: =(I32-J32)/(1+$B$11/100)^A32 -> 9066283.7
A33: =A32+1 -> 13 | B33: =$B$13*12*(1+$B$14/100)^(A33-1) -> 941528.51 | C33: =$E$5+$E$6/12-$B$13*(1+$B$14/100)^(A33-1) -> -9707.8866 | D33: =D32+C33*12 -> 5868626.7 | E33: =$B$5*(1+$B$10/100)^A33 -> 34522712 | F33: =IF(A33>=$B$8,0,MAX(0,-FV($B$7/1200,A33*12,-$E$5,$B$6))) -> 3939131.8 | G33: =E33-E33*'Common Assumptions'!$B$29/100-MAX(0,E33-$B$5-E33*'Common Assumptions'!$B$29/100)*'Common Assumptions'!$B$28/100-F33 -> 27518241 | H33: =G33/(1+$B$11/100)^A33 -> 12901625 | I33: =I32*(1+$B$12/1200)^12+FV($B$12/1200,12,-C33,0,0) -> 22386824 | J33: =MAX(0,I33-D33-$B$16)*$B$15/100 -> 2049149.7 | K33: =(I33-J33)/(1+$B$11/100)^A33 -> 9535095.5
... A40: =A39+1 -> 20 | B40: =$B$13*12*(1+$B$14/100)^(A40-1) -> 1834772.7 | C40: =$E$5+$E$6/12-$B$13*(1+$B$14/100)^(A40-1) -> -84144.903 | D40: =D39+C40*12 -> 1818177.6 | E40: =$B$5*(1+$B$10/100)^A40 -> 67274999 | F40: =IF(A40>=$B$8,0,MAX(0,-FV($B$7/1200,A40*12,-$E$5,$B$6))) -> 0 | G40: =E40-E40*'Common Assumptions'!$B$29/100-MAX(0,E40-$B$5-E40*'Common Assumptions'!$B$29/100)*'Common Assumptions'!$B$28/100-F40 -> 60115625 | H40: =G40/(1+$B$11/100)^A40 -> 18744336 | I40: =I39*(1+$B$12/1200)^12+FV($B$12/1200,12,-C40,0,0) -> 46015989 | J40: =MAX(0,I40-D40-$B$16)*$B$15/100 -> 5509101.5 | K40: =(I40-J40)/(1+$B$11/100)^A40 -> 12630239

Sheet Home Loan Analysis
A1: Property Price (₹) | B1: 10000000 | C1: Purchase price used as the starting value of the property.
A2: Loan Amount (₹) | B2: 7500000 | C2: Principal financed through the home loan.
A3: Loan Interest (% per year) | B3: ='Common Assumptions'!$B$7 -> 7.5 | C3: Annual nominal loan rate; the EMI calculation uses a monthly rate.
A4: Tenure (years) | B4: 20 | C4: Loan and investment comparison period in years.
A5: Maintenance (% per year) | B5: ='Common Assumptions'!$B$9 -> 1 | C5: Annual maintenance assumption; this model keeps the first-year rupee amount flat.
A6: Property Appreciation (% per year) | B6: ='Common Assumptions'!$B$8 -> 10 | C6: Expected annual compound growth rate of the property value.
A7: Inflation (% per year) | B7: ='Common Assumptions'!$B$5 -> 6 | C7: Annual rate used to convert future amounts into today’s purchasing power.
A8: SIP Return (% per year) | B8: ='Common Assumptions'!$B$6 -> 12 | C8: Expected annual SIP return; monthly contributions are compounded monthly.
A10: EMI & PROPERTY SUMMARY
A11: Down Payment | B11: =B1-B2 -> 2500000 | C11: Property price less the loan amount; also used as the SIP lump sum.
A12: Monthly EMI | B12: =PMT(B3/1200,B4*12,-B2) -> 60419.49 | C12: Fixed monthly loan payment of principal and interest.
A13: Total EMI Paid | B13: =B12*B4*12 -> 14500677 | C13: Monthly EMI multiplied by the full number of loan months.
A14: Net Interest Paid | B14: =B13-B2 -> 7000677.5 | C14: Total EMI paid less the original loan principal.
A15: Loan-to-Value Ratio | B15: =B2/B1 -> 0.75 | C15: =IF(OR('Common Assumptions'!$B$23="",'Common Assumptions'!$B$24="",'Common Assumptions'!$B$25="",'Common Assumptions'!$B$26="",'Common Assumptions'!$B$27=""),"",IF(B15>IF($B$2<='Common Assumptions'!$B$23,'Common Assumptions'!$B$25/100,IF($B$2<='Common Assumptions'!$B$24,'Common Assumptions'!$B$26/100,'Common Assumptions'!$B$27/100)),"Above regulatory LTV limit for this loan size: verify with your lender","Within configured LTV limit")) -> Within configured LTV limit
A16: First-Year Maintenance | B16: =B1*B5/100 -> 100000 | C16: Property price multiplied by the annual maintenance rate.
A17: Total Maintenance (20 Years) | B17: =B16*B4 -> 2000000 | C17: First-year maintenance multiplied by tenure; no annual escalation is modeled.
A18: Property Future Value (Gross Nominal) | B18: =B1*(1+B6/100)^B4 -> 67274999 | C18: Estimated property value at the end of the tenure before inflation adjustment.
A19: Property Future Value (Gross Real) | B19: =B18/(1+B7/100)^B4 -> 20976663 | C19: Gross future property value expressed in today’s rupees.
A20: Net Property Gain (After Maintenance & Interest) | B20: =B18-B1-B17-B14-(B18*'Common Assumptions'!$B$29/100)-(MAX(0,B18-B1-(B18*'Common Assumptions'!$B$29/100)) * 'Common Assumptions'!$B$28/100) -> 41114947 | C20: Nominal property sale value less purchase price, maintenance, loan interest, modeled selling cost, and modeled tax on sale gain.
A21: Real Property Gain (After Financing & Maintenance) | B21: =(B18-(B18*'Common Assumptions'!$B$29/100)-(MAX(0,B18-B1-(B18*'Common Assumptions'!$B$29/100)) * 'Common Assumptions'!$B$28/100))/(1+B7/100)^B4-B11-B12*12*IF(B7=0,B4,(1-(1+B7/100)^(-B4))/(B7/100))-IF(B7=0,B16*B4,B16*(1-(1+B7/100)^(-B4))/(B7/100)) -> 6781262.4 | C21: Net property sale proceeds in today's rupees less the down payment and present values of monthly EMIs and maintenance.
A23: SIP INVESTMENT SUMMARY
A24: Lump Sum Investment | B24: =B11 -> 2500000 | C24: One-time investment equal to the house down payment.
A25: Monthly SIP | B25: =B12 -> 60419.49 | C25: Monthly investment equal to the home-loan EMI.
A26: Total Amount Invested | B26: =B24+B25*B4*12 -> 17000677 | C26: Lump sum plus all monthly SIP contributions; returns are excluded.
A27: SIP Future Value (Nominal) | B27: =B24*(1+B8/1200)^(B4*12)+FV(B8/1200,B4*12,-B25,0,0) -> 87001688 | C27: Future value of the lump sum and monthly SIP contributions using monthly compounding before tax and inflation.
A28: Inflation-Adjusted SIP Value | B28: =B27/(1+B7/100)^B4 -> 27127538 | C28: Nominal SIP future value expressed in today’s rupees.
A29: Investment Gain (Nominal) | B29: =B27-B26 -> 70001011 | C29: SIP future value less total contributions, before tax.
A30: ="LTCG Tax ("&TEXT('Common Assumptions'!$B$12/100,"0.0%")&", ₹"&TEXT('Common Assumptions'!$B$13/100000,"0.00")&"L Exemption)" -> LTCG Tax (12.5%, ₹1.25L Exemption) | B30: =MAX(0,B29-'Common Assumptions'!$B$13)*'Common Assumptions'!$B$12/100 -> 8734501.4 | C30: ="Tax on the nominal investment gain above ₹"&TEXT('Common Assumptions'!$B$13,"##,##,##0")&", using the shared illustrative LTCG rate." -> Tax on the nominal investment gain above ₹1,25,000, using the shared illustrative LTCG rate.
A31: Post-Tax Investment Gain (Nominal) | B31: =B29-B30 -> 61266509 | C31: Nominal investment gain remaining after deducting the modeled LTCG tax.
A32: Post-Tax Future Value (Nominal) | B32: =B26+B31 -> 78267187 | C32: Total amount invested plus the post-tax nominal investment gain; this is the post-tax corpus after 20 years.
A33: Post-Tax Future Value (Real) | B33: =B32/(1+B7/100)^B4 -> 24404079 | C33: Post-tax future value after adjusting the full corpus for inflation; this is the value after 20 years in today’s rupees.
A34: Real Gain After LTCG & Inflation | B34: =B33-B35 -> 13587997 | C34: Inflation-adjusted post-tax future value less the present value of all SIP contributions, discounted consistently with the house-side cost methodology.
A35: Present Value of SIP Contributions (Real) | B35: =B24+B25*12*IF(B7=0,B4,(1-(1+B7/100)^(-B4))/(B7/100)) -> 10816081 | C35: Lump sum paid today plus each monthly SIP contribution discounted to present value using the same year-by-year inflation convention applied to home-loan interest.
A36: HOUSE VS SIP — DECISION ANALYSIS
A37: Comparison uses the assumptions above over the same 20-year horizon.
A39: Metric | B39: House | C39: SIP
A40: Total modeled cash outlay | B40: =B11+B13+B17 -> 19000677 | C40: =B26 -> 17000677
A41: Nominal future value | B41: =B18-(B18*'Common Assumptions'!$B$29/100)-(MAX(0,B18-B1-(B18*'Common Assumptions'!$B$29/100)) * 'Common Assumptions'!$B$28/100) -> 60115625 | C41: =B32 -> 78267187
A42: Inflation-adjusted future value | B42: =B41/(1+B7/100)^B4 -> 18744336 | C42: =B33 -> 24404079
A43: Real gain after modeled costs / tax | B43: =B21 -> 6781262.4 | C43: =B34 -> 13587997
...

Sheet EMI Calculator
A1: EMI CALCULATOR & YEARLY REPAYMENT SCHEDULE
A2: Edit the loan inputs below; the summary and annual amortization schedule recalculate automatically.
A4: LOAN INPUTS | D4: LOAN SUMMARY
A5: Loan Amount (₹) | B5: 2000000 | D5: Monthly EMI | E5: =-PMT($B$6/1200,$B$7*12,$B$5) -> 16111.864
A6: Interest Rate (% per year) | B6: ='Common Assumptions'!$B$7 -> 7.5 | D6: Total Payment | E6: =E5*$B$7*12 -> 3866847.3
A7: Tenure (years) | B7: 20 | D7: Total Interest | E7: =E6-$B$5 -> 1866847.3
D8: Total Principal | E8: =$B$5 -> 2000000
A10: YEARLY PAYMENT SCHEDULE
A11: Year | B11: Opening Balance | C11: EMI Paid | D11: Principal Paid | E11: Interest Paid | F11: Closing Balance
A12: =1 -> 1 | B12: =$B$5 -> 2000000 | C12: =$E$5*12 -> 193342.37 | D12: =-CUMPRINC($B$6/1200,$B$7*12,$B$5,1,12,0) -> 44863.741 | E12: =-CUMIPMT($B$6/1200,$B$7*12,$B$5,1,12,0) -> 148478.63 | F12: =MAX(0,B12-D12) -> 1955136.3
A13: =A12+1 -> 2 | B13: =F12 -> 1955136.3 | C13: =$E$5*12 -> 193342.37 | D13: =-CUMPRINC($B$6/1200,$B$7*12,$B$5,(A13-1)*12+1,A13*12,0) -> 48346.629 | E13: =-CUMIPMT($B$6/1200,$B$7*12,$B$5,(A13-1)*12+1,A13*12,0) -> 144995.74 | F13: =MAX(0,B13-D13) -> 1906789.6
A14: =A13+1 -> 3 | B14: =F13 -> 1906789.6 | C14: =$E$5*12 -> 193342.37 | D14: =-CUMPRINC($B$6/1200,$B$7*12,$B$5,(A14-1)*12+1,A14*12,0) -> 52099.904 | E14: =-CUMIPMT($B$6/1200,$B$7*12,$B$5,(A14-1)*12+1,A14*12,0) -> 141242.46 | F14: =MAX(0,B14-D14) -> 1854689.7
A15: =A14+1 -> 4 | B15: =F14 -> 1854689.7 | C15: =$E$5*12 -> 193342.37 | D15: =-CUMPRINC($B$6/1200,$B$7*12,$B$5,(A15-1)*12+1,A15*12,0) -> 56144.555 | E15: =-CUMIPMT($B$6/1200,$B$7*12,$B$5,(A15-1)*12+1,A15*12,0) -> 137197.81 | F15: =MAX(0,B15-D15) -> 1798545.2
A16: =A15+1 -> 5 | B16: =F15 -> 1798545.2 | C16: =$E$5*12 -> 193342.37 | D16: =-CUMPRINC($B$6/1200,$B$7*12,$B$5,(A16-1)*12+1,A16*12,0) -> 60503.203 | E16: =-CUMIPMT($B$6/1200,$B$7*12,$B$5,(A16-1)*12+1,A16*12,0) -> 132839.16 | F16: =MAX(0,B16-D16) -> 1738042
A17: =A16+1 -> 6 | B17: =F16 -> 1738042 | C17: =$E$5*12 -> 193342.37 | D17: =-CUMPRINC($B$6/1200,$B$7*12,$B$5,(A17-1)*12+1,A17*12,0) -> 65200.223 | E17: =-CUMIPMT($B$6/1200,$B$7*12,$B$5,(A17-1)*12+1,A17*12,0) -> 128142.14 | F17: =MAX(0,B17-D17) -> 1672841.7
A18: =A17+1 -> 7 | B18: =F17 -> 1672841.7 | C18: =$E$5*12 -> 193342.37 | D18: =-CUMPRINC($B$6/1200,$B$7*12,$B$5,(A18-1)*12+1,A18*12,0) -> 70261.886 | E18: =-CUMIPMT($B$6/1200,$B$7*12,$B$5,(A18-1)*12+1,A18*12,0) -> 123080.48 | F18: =MAX(0,B18-D18) -> 1602579.9
A19: =A18+1 -> 8 | B19: =F18 -> 1602579.9 | C19: =$E$5*12 -> 193342.37 | D19: =-CUMPRINC($B$6/1200,$B$7*12,$B$5,(A19-1)*12+1,A19*12,0) -> 75716.499 | E19: =-CUMIPMT($B$6/1200,$B$7*12,$B$5,(A19-1)*12+1,A19*12,0) -> 117625.87 | F19: =MAX(0,B19-D19) -> 1526863.4
A20: =A19+1 -> 9 | B20: =F19 -> 1526863.4 | C20: =$E$5*12 -> 193342.37 | D20: =-CUMPRINC($B$6/1200,$B$7*12,$B$5,(A20-1)*12+1,A20*12,0) -> 81594.568 | E20: =-CUMIPMT($B$6/1200,$B$7*12,$B$5,(A20-1)*12+1,A20*12,0) -> 111747.8 | F20: =MAX(0,B20-D20) -> 1445268.8
A21: =A20+1 -> 10 | B21: =F20 -> 1445268.8 | C21: =$E$5*12 -> 193342.37 | D21: =-CUMPRINC($B$6/1200,$B$7*12,$B$5,(A21-1)*12+1,A21*12,0) -> 87928.966 | E21: =-CUMIPMT($B$6/1200,$B$7*12,$B$5,(A21-1)*12+1,A21*12,0) -> 105413.4 | F21: =MAX(0,B21-D21) -> 1357339.8
A22: =A21+1 -> 11 | B22: =F21 -> 1357339.8 | C22: =$E$5*12 -> 193342.37 | D22: =-CUMPRINC($B$6/1200,$B$7*12,$B$5,(A22-1)*12+1,A22*12,0) -> 94755.12 | E22: =-CUMIPMT($B$6/1200,$B$7*12,$B$5,(A22-1)*12+1,A22*12,0) -> 98587.246 | F22: =MAX(0,B22-D22) -> 1262584.7
A23: =A22+1 -> 12 | B23: =F22 -> 1262584.7 | C23: =$E$5*12 -> 193342.37 | D23: =-CUMPRINC($B$6/1200,$B$7*12,$B$5,(A23-1)*12+1,A23*12,0) -> 102111.21 | E23: =-CUMIPMT($B$6/1200,$B$7*12,$B$5,(A23-1)*12+1,A23*12,0) -> 91231.16 | F23: =MAX(0,B23-D23) -> 1160473.5
A24: =A23+1 -> 13 | B24: =F23 -> 1160473.5 | C24: =$E$5*12 -> 193342.37 | D24: =-CUMPRINC($B$6/1200,$B$7*12,$B$5,(A24-1)*12+1,A24*12,0) -> 110038.36 | E24: =-CUMIPMT($B$6/1200,$B$7*12,$B$5,(A24-1)*12+1,A24*12,0) -> 83304.002 | F24: =MAX(0,B24-D24) -> 1050435.1
... A31: =A30+1 -> 20 | B31: =F30 -> 185711.66 | C31: =$E$5*12 -> 193342.37 | D31: =-CUMPRINC($B$6/1200,$B$7*12,$B$5,(A31-1)*12+1,A31*12,0) -> 185711.66 | E31: =-CUMIPMT($B$6/1200,$B$7*12,$B$5,(A31-1)*12+1,A31*12,0) -> 7630.7069 | F31: =MAX(0,B31-D31) -> 0
A33: HOW TO READ THE RESULTS
A34: ="1. A loan of ₹"&TEXT($B$5,"##,##,##0")&" at "&TEXT($B$6/100,"0.00%")&" for "&TEXT($B$7,"0")&" years requires a monthly EMI of ₹"&TEXT($E$5,"##,##,##0")&"." -> 1. A loan of ₹20,00,000 at 7.50% for 20 years requires a monthly EMI of ₹16,112.
A35: ="2. Total repayment over "&TEXT($B$7,"0")&" years is ₹"&TEXT($E$6,"##,##,##0")&", consisting of ₹"&TEXT($E$8,"##,##,##0")&" principal and ₹"&TEXT($E$7,"##,##,##0")&" interest." -> 2. Total repayment over 20 years is ₹38,66,847, consisting of ₹20,00,000 principal and ₹18,66,847 interest.
A36: ="3. Interest represents "&TEXT($E$7/$E$6,"0.0%")&" of total repayments; the remaining "&TEXT($E$8/$E$6,"0.0%")&" repays principal." -> 3. Interest represents 48.3% of total repayments; the remaining 51.7% repays principal.
A37: ="4. In year 1, ₹"&TEXT($D$12,"##,##,##0")&" of payments reduces principal and ₹"&TEXT($E$12,"##,##,##0")&" pays interest; this mix shifts toward principal over time." -> 4. In year 1, ₹44,864 of payments reduces principal and ₹1,48,479 pays interest; this mix shifts toward principal over time.
A39: INPUT GUIDE
A40: Input | C40: How it affects the model | F40: Current value
A41: Loan amount | C41: Principal borrowed. A larger amount increases the EMI, total repayment, and total interest proportionally. | F41: =B5 -> 2000000
A42: Annual interest rate | C42: Nominal annual borrowing rate divided by 12 for the monthly EMI and amortization calculations. | F42: =B6 -> 7.5
A43: Tenure | C43: Repayment period in years. A longer tenure usually lowers EMI but increases total interest. | F43: =B7 -> 20
A45: OUTPUT & CALCULATION FLOW
A46: Output | C46: Meaning / calculation flow
A47: Monthly EMI | C47: Fixed monthly payment calculated using the loan amount, monthly interest rate, and total number of monthly payments.
A48: Total payment | C48: Monthly EMI × 12 × tenure. This is the total cash paid to the lender if the rate and schedule remain unchanged.
A49: Total interest | C49: Total payment less the original loan amount. It is the modeled cost of borrowing before fees, taxes, or benefits.
A50: Opening balance | C50: Outstanding principal at the beginning of each year.
A51: Principal paid | C51: The part of that year’s EMIs that reduces the outstanding loan balance.
...

Sheet SIP Growth
A1: SIP GROWTH & YEARLY VALUE SCHEDULE
A2: Edit the assumptions below; the summary and yearly schedule recalculate automatically.
A4: INVESTMENT INPUTS | D4: INVESTMENT SUMMARY
A5: Lumpsum at start | B5: 0 | D5: Total Amount Invested | E5: =$B$5+$B$6*$B$8*12 -> 4800000
A6: Monthly SIP Amount (₹) | B6: 20000 | D6: Future Value (Nominal) | E6: =$B$5*(1+$B$7/1200)^($B$8*12)+FV($B$7/1200,$B$8*12,-$B$6,0,0) -> 19785107
A7: Expected Return (% per year) | B7: ='Common Assumptions'!$B$6 -> 12 | D7: Investment Gain (Nominal) | E7: =E6-E5 -> 14985107
A8: Tenure (years) | B8: 20 | D8: Estimated LTCG Tax | E8: =MAX(0,E7-$B$11)*$B$10/100 -> 1857513.4
A9: Inflation (% per year) | B9: ='Common Assumptions'!$B$5 -> 6 | D9: Post-Tax Value (Nominal) | E9: =E6-E8 -> 17927594
A10: LTCG Tax Rate (%) | B10: ='Common Assumptions'!$B$12 -> 12.5 | D10: Post-Tax Value (Real) | E10: =E9/(1+$B$9/100)^$B$8 -> 5589908.5
A11: LTCG Exemption (₹) | B11: ='Common Assumptions'!$B$13 -> 125000 | D11: Real Gain vs Contributions (contributions in today's rupees) | E11: =E10-($B$5+IF($B$9=0,$B$6*12*$B$8,$B$6*12*(1-(1+$B$9/100)^(-$B$8))/($B$9/100))) -> 2837127.4
A13: Tax assumption: each row estimates tax if the full portfolio were redeemed at that year-end and all gains qualified for Section 112A LTCG. It excludes cess, surcharge, expense ratios, and the short-term status of recent SIP instalments.
A15: YEARLY SIP GROWTH SCHEDULE
A16: Year | B16: Opening Value | C16: Annual SIP | D16: Total Invested | E16: Nominal Value | F16: Nominal Gain | G16: Estimated LTCG Tax | H16: Post-Tax Value | I16: Post-Tax Real Value
A17: =IF(ROW()-16<=$B$8,ROW()-16,"") -> 1 | B17: =IF($A17="","",$B$5) -> 0 | C17: =IF($A17="","",$B$6*12) -> 240000 | D17: =IF($A17="","",$B$5+C17) -> 240000 | E17: =IF($A17="","",$B$5*(1+$B$7/1200)^12+FV($B$7/1200,12,-$B$6,0,0)) -> 253650.06 | F17: =IF($A17="","",E17-D17) -> 13650.06 | G17: =IF($A17="","",MAX(0,F17-$B$11)*$B$10/100) -> 0 | H17: =IF($A17="","",E17-G17) -> 253650.06 | I17: =IF($A17="","",H17/(1+$B$9/100)^A17) -> 239292.51
A18: =IF(ROW()-16<=$B$8,ROW()-16,"") -> 2 | B18: =IF($A18="","",E17) -> 253650.06 | C18: =IF($A18="","",$B$6*12) -> 240000 | D18: =IF($A18="","",D17+C18) -> 480000 | E18: =IF($A18="","",E17*(1+$B$7/1200)^12+FV($B$7/1200,12,-$B$6,0,0)) -> 539469.3 | F18: =IF($A18="","",E18-D18) -> 59469.297 | G18: =IF($A18="","",MAX(0,F18-$B$11)*$B$10/100) -> 0 | H18: =IF($A18="","",E18-G18) -> 539469.3 | I18: =IF($A18="","",H18/(1+$B$9/100)^A18) -> 480125.75
A19: =IF(ROW()-16<=$B$8,ROW()-16,"") -> 3 | B19: =IF($A19="","",E18) -> 539469.3 | C19: =IF($A19="","",$B$6*12) -> 240000 | D19: =IF($A19="","",D18+C19) -> 720000 | E19: =IF($A19="","",E18*(1+$B$7/1200)^12+FV($B$7/1200,12,-$B$6,0,0)) -> 861537.57 | F19: =IF($A19="","",E19-D19) -> 141537.57 | G19: =IF($A19="","",MAX(0,F19-$B$11)*$B$10/100) -> 2067.1959 | H19: =IF($A19="","",E19-G19) -> 859470.37 | I19: =IF($A19="","",H19/(1+$B$9/100)^A19) -> 721627.9
A20: =IF(ROW()-16<=$B$8,ROW()-16,"") -> 4 | B20: =IF($A20="","",E19) -> 861537.57 | C20: =IF($A20="","",$B$6*12) -> 240000 | D20: =IF($A20="","",D19+C20) -> 960000 | E20: =IF($A20="","",E19*(1+$B$7/1200)^12+FV($B$7/1200,12,-$B$6,0,0)) -> 1224452.2 | F20: =IF($A20="","",E20-D20) -> 264452.16 | G20: =IF($A20="","",MAX(0,F20-$B$11)*$B$10/100) -> 17431.519 | H20: =IF($A20="","",E20-G20) -> 1207020.6 | I20: =IF($A20="","",H20/(1+$B$9/100)^A20) -> 956073.4
A21: =IF(ROW()-16<=$B$8,ROW()-16,"") -> 5 | B21: =IF($A21="","",E20) -> 1224452.2 | C21: =IF($A21="","",$B$6*12) -> 240000 | D21: =IF($A21="","",D20+C21) -> 1200000 | E21: =IF($A21="","",E20*(1+$B$7/1200)^12+FV($B$7/1200,12,-$B$6,0,0)) -> 1633393.4 | F21: =IF($A21="","",E21-D21) -> 433393.4 | G21: =IF($A21="","",MAX(0,F21-$B$11)*$B$10/100) -> 38549.175 | H21: =IF($A21="","",E21-G21) -> 1594844.2 | I21: =IF($A21="","",H21/(1+$B$9/100)^A21) -> 1191760.4
A22: =IF(ROW()-16<=$B$8,ROW()-16,"") -> 6 | B22: =IF($A22="","",E21) -> 1633393.4 | C22: =IF($A22="","",$B$6*12) -> 240000 | D22: =IF($A22="","",D21+C22) -> 1440000 | E22: =IF($A22="","",E21*(1+$B$7/1200)^12+FV($B$7/1200,12,-$B$6,0,0)) -> 2094198.6 | F22: =IF($A22="","",E22-D22) -> 654198.62 | G22: =IF($A22="","",MAX(0,F22-$B$11)*$B$10/100) -> 66149.828 | H22: =IF($A22="","",E22-G22) -> 2028048.8 | I22: =IF($A22="","",H22/(1+$B$9/100)^A22) -> 1429694.4
A23: =IF(ROW()-16<=$B$8,ROW()-16,"") -> 7 | B23: =IF($A23="","",E22) -> 2094198.6 | C23: =IF($A23="","",$B$6*12) -> 240000 | D23: =IF($A23="","",D22+C23) -> 1680000 | E23: =IF($A23="","",E22*(1+$B$7/1200)^12+FV($B$7/1200,12,-$B$6,0,0)) -> 2613445.5 | F23: =IF($A23="","",E23-D23) -> 933445.49 | G23: =IF($A23="","",MAX(0,F23-$B$11)*$B$10/100) -> 101055.69 | H23: =IF($A23="","",E23-G23) -> 2512389.8 | I23: =IF($A23="","",H23/(1+$B$9/100)^A23) -> 1670882.7
A24: =IF(ROW()-16<=$B$8,ROW()-16,"") -> 8 | B24: =IF($A24="","",E23) -> 2613445.5 | C24: =IF($A24="","",$B$6*12) -> 240000 | D24: =IF($A24="","",D23+C24) -> 1920000 | E24: =IF($A24="","",E23*(1+$B$7/1200)^12+FV($B$7/1200,12,-$B$6,0,0)) -> 3198545.9 | F24: =IF($A24="","",E24-D24) -> 1278545.9 | G24: =IF($A24="","",MAX(0,F24-$B$11)*$B$10/100) -> 144193.23 | H24: =IF($A24="","",E24-G24) -> 3054352.6 | I24: =IF($A24="","",H24/(1+$B$9/100)^A24) -> 1916338.6
A25: =IF(ROW()-16<=$B$8,ROW()-16,"") -> 9 | B25: =IF($A25="","",E24) -> 3198545.9 | C25: =IF($A25="","",$B$6*12) -> 240000 | D25: =IF($A25="","",D24+C25) -> 2160000 | E25: =IF($A25="","",E24*(1+$B$7/1200)^12+FV($B$7/1200,12,-$B$6,0,0)) -> 3857851.6 | F25: =IF($A25="","",E25-D25) -> 1697851.6 | G25: =IF($A25="","",MAX(0,F25-$B$11)*$B$10/100) -> 196606.45 | H25: =IF($A25="","",E25-G25) -> 3661245.1 | I25: =IF($A25="","",H25/(1+$B$9/100)^A25) -> 2167085.4
A26: =IF(ROW()-16<=$B$8,ROW()-16,"") -> 10 | B26: =IF($A26="","",E25) -> 3857851.6 | C26: =IF($A26="","",$B$6*12) -> 240000 | D26: =IF($A26="","",D25+C26) -> 2400000 | E26: =IF($A26="","",E25*(1+$B$7/1200)^12+FV($B$7/1200,12,-$B$6,0,0)) -> 4600773.8 | F26: =IF($A26="","",E26-D26) -> 2200773.8 | G26: =IF($A26="","",MAX(0,F26-$B$11)*$B$10/100) -> 259471.72 | H26: =IF($A26="","",E26-G26) -> 4341302.1 | I26: =IF($A26="","",H26/(1+$B$9/100)^A26) -> 2424160.4
A27: =IF(ROW()-16<=$B$8,ROW()-16,"") -> 11 | B27: =IF($A27="","",E26) -> 4600773.8 | C27: =IF($A27="","",$B$6*12) -> 240000 | D27: =IF($A27="","",D26+C27) -> 2640000 | E27: =IF($A27="","",E26*(1+$B$7/1200)^12+FV($B$7/1200,12,-$B$6,0,0)) -> 5437917.1 | F27: =IF($A27="","",E27-D27) -> 2797917.1 | G27: =IF($A27="","",MAX(0,F27-$B$11)*$B$10/100) -> 334114.64 | H27: =IF($A27="","",E27-G27) -> 5103802.5 | I27: =IF($A27="","",H27/(1+$B$9/100)^A27) -> 2688619.5
A28: =IF(ROW()-16<=$B$8,ROW()-16,"") -> 12 | B28: =IF($A28="","",E27) -> 5437917.1 | C28: =IF($A28="","",$B$6*12) -> 240000 | D28: =IF($A28="","",D27+C28) -> 2880000 | E28: =IF($A28="","",E27*(1+$B$7/1200)^12+FV($B$7/1200,12,-$B$6,0,0)) -> 6381231.2 | F28: =IF($A28="","",E28-D28) -> 3501231.2 | G28: =IF($A28="","",MAX(0,F28-$B$11)*$B$10/100) -> 422028.9 | H28: =IF($A28="","",E28-G28) -> 5959202.3 | I28: =IF($A28="","",H28/(1+$B$9/100)^A28) -> 2961541
A29: =IF(ROW()-16<=$B$8,ROW()-16,"") -> 13 | B29: =IF($A29="","",E28) -> 6381231.2 | C29: =IF($A29="","",$B$6*12) -> 240000 | D29: =IF($A29="","",D28+C29) -> 3120000 | E29: =IF($A29="","",E28*(1+$B$7/1200)^12+FV($B$7/1200,12,-$B$6,0,0)) -> 7444181.1 | F29: =IF($A29="","",E29-D29) -> 4324181.1 | G29: =IF($A29="","",MAX(0,F29-$B$11)*$B$10/100) -> 524897.64 | H29: =IF($A29="","",E29-G29) -> 6919283.4 | I29: =IF($A29="","",H29/(1+$B$9/100)^A29) -> 3244030.1
... A56: =IF(ROW()-16<=$B$8,ROW()-16,"") | B56: =IF($A56="","",E55) | C56: =IF($A56="","",$B$6*12) | D56: =IF($A56="","",D55+C56) | E56: =IF($A56="","",E55*(1+$B$7/1200)^12+FV($B$7/1200,12,-$B$6,0,0)) | F56: =IF($A56="","",E56-D56) | G56: =IF($A56="","",MAX(0,F56-$B$11)*$B$10/100) | H56: =IF($A56="","",E56-G56) | I56: =IF($A56="","",H56/(1+$B$9/100)^A56)
A58: HOW TO READ THE RESULTS
A59: ="1. Over "&TEXT($B$8,"0")&" years, total contributions are ₹"&TEXT($E$5,"##,##,##0")&" and the projected nominal portfolio is ₹"&TEXT($E$6,"##,##,##0")&"." -> 1. Over 20 years, total contributions are ₹48,00,000 and the projected nominal portfolio is ₹1,97,85,107.
A60: ="2. The projected nominal gain is ₹"&TEXT($E$7,"##,##,##0")&"; estimated tax on a full final redemption is ₹"&TEXT($E$8,"##,##,##0")&", leaving ₹"&TEXT($E$9,"##,##,##0")&" nominally." -> 2. The projected nominal gain is ₹1,49,85,107; estimated tax on a full final redemption is ₹18,57,513, leaving ₹1,79,27,594 nominally.
A61: ="3. After adjusting the post-tax corpus for "&TEXT($B$9/100,"0.0%")&" annual inflation, its value in today’s rupees is ₹"&TEXT($E$10,"##,##,##0")&"." -> 3. After adjusting the post-tax corpus for 6.0% annual inflation, its value in today’s rupees is ₹55,89,909.
A62: ="4. Contributions are brought to today's rupees year by year (each year's twelve instalments divided by (1 + inflation) for that year). The real gain of ₹" & TEXT($E$11,"##,##,##0") & " compares the post-tax real value with those contributions." -> 4. Contributions are brought to today's rupees year by year (each year's twelve instalments divided by (1 + inflation) for that year). The real gain of ₹28,37,127 compares the post-tax real value with those contributions.
A64: INPUT GUIDE
A65: Input | C65: How it affects the model | G65: Current value
A66: Lumpsum at start | C66: One-time amount invested immediately; it compounds for the entire selected tenure. | G66: =B5 -> 0
A67: Monthly SIP amount | C67: Contribution made at the end of every month; annual contribution shown in the table equals 12 monthly SIPs. | G67: =B6 -> 20000
A68: Expected annual return | C68: Nominal annual return divided by 12 for monthly compounding; it is an assumption, not a guaranteed return. | G68: =B7 -> 12
A69: Tenure | C69: Number of years projected and the number of yearly rows generated in the schedule. | G69: =B8 -> 20
A70: Inflation | C70: Used to discount each year’s post-tax nominal value into today’s purchasing power. | G70: =B9 -> 6
A71: LTCG tax rate | C71: Tax percentage applied to estimated qualifying gains above the exemption on a full redemption. | G71: =B10 -> 12.5
...

Sheet Expense Ratio Impact
A1: MUTUAL FUND EXPENSE-RATIO IMPACT CALCULATOR
A2: Compare direct and regular plans using the same gross return; the difference shows how annual fund expenses compound into a long-term rupee cost.
A4: MODEL INPUTS | D4: SELECTED-HORIZON SUMMARY | H4: HOW TO READ THE RESULT
A5: Lumpsum at Start (₹) | B5: 0 | D5: Direct Net Return | E5: =B7-B8 -> 11.5 | H5: ="1. At year "&TEXT($B$10,"0")&", the higher expense ratio reduces pre-tax wealth by "&TEXT($E$10,"₹#,##0")&"." -> 1. At year 20, the higher expense ratio reduces pre-tax wealth by ₹22,91,924.
A6: Monthly SIP Amount (₹) | B6: 20000 | D6: Regular Net Return | E6: =B7-B9 -> 10.5 | H6: ="2. In today’s rupees after simplified tax, the wealth gap is "&TEXT($E$13,"₹#,##0")&"." -> 2. In today’s rupees after simplified tax, the wealth gap is ₹6,25,304.
A7: Gross Return Before Expenses (% p.a.) | B7: ='Common Assumptions'!$B$6 -> 12 | D7: Total Amount Invested | E7: =B5+B6*12*B10 -> 4800000 | H7: ="3. The annual TER difference is "&TEXT($B$9-$B$8,"0.00")&" percentage points; the cost accelerates as the portfolio grows." -> 3. The annual TER difference is 1.00 percentage points; the cost accelerates as the portfolio grows.
A8: Direct Plan Expense Ratio (% p.a.) | B8: ='Common Assumptions'!$B$10 -> 0.5 | D8: Direct Value Before Tax | E8: {=INDEX(C27:C56,B10)} -> 18502021 | H8: 4. Both plans are assumed to earn the same gross return before expenses; only the expense ratio differs.
A9: Regular Plan Expense Ratio (% p.a.) | B9: ='Common Assumptions'!$B$11 -> 1.5 | D9: Regular Value Before Tax | E9: {=INDEX(G27:G56,B10)} -> 16210098 | H9: 5. Tax is estimated as if the full portfolio were redeemed at each year-end and all gains qualified for the selected LTCG treatment.
A10: Selected Horizon (5–30 years) | B10: 20 | D10: Wealth Lost Before Tax | E10: =E8-E9 -> 2291923.7 | H10: 6. Returns, inflation, expenses, and tax inputs are assumptions—not forecasts or guarantees.
A11: Inflation (% p.a.) | B11: ='Common Assumptions'!$B$5 -> 6 | D11: Direct Post-Tax Value (Real) | E11: {=INDEX(F27:F56,B10)} -> 5239845.2
A12: LTCG Tax Rate (%) | B12: ='Common Assumptions'!$B$12 -> 12.5 | D12: Regular Post-Tax Value (Real) | E12: {=INDEX(J27:J56,B10)} -> 4614541.7
A13: LTCG Exemption (₹) | B13: ='Common Assumptions'!$B$13 -> 125000 | D13: Real Wealth Lost to Higher TER | E13: =E11-E12 -> 625303.56
A16: 5–30 YEAR MILESTONE COMPARISON
A17: Year | B17: Total Invested | C17: Direct Value Before Tax | D17: Regular Value Before Tax | E17: Pre-Tax Wealth Lost | F17: Direct Post-Tax Real | G17: Regular Post-Tax Real | H17: Real Wealth Lost
A18: 5 | B18: {=INDEX($B$27:$B$56,$A18)} -> 1200000 | C18: {=INDEX($C$27:$C$56,$A18)} -> 1611697.8 | D18: {=INDEX($G$27:$G$56,$A18)} -> 1569378.2 | E18: =C18-D18 -> 42319.582 | F18: {=INDEX($F$27:$F$56,$A18)} -> 1177574.7 | G18: {=INDEX($J$27:$J$56,$A18)} -> 1149904 | H18: =F18-G18 -> 27670.697
A19: 10 | B19: {=INDEX($B$27:$B$56,$A19)} -> 2400000 | C19: {=INDEX($C$27:$C$56,$A19)} -> 4468064.6 | D19: {=INDEX($G$27:$G$56,$A19)} -> 4216296.3 | E19: =C19-D19 -> 251768.28 | F19: {=INDEX($F$27:$F$56,$A19)} -> 2359319.3 | G19: {=INDEX($J$27:$J$56,$A19)} -> 2236306.4 | H19: =F19-G19 -> 123012.83
A20: 15 | B20: {=INDEX($B$27:$B$56,$A20)} -> 3600000 | C20: {=INDEX($C$27:$C$56,$A20)} -> 9530323 | D20: {=INDEX($G$27:$G$56,$A20)} -> 8680596.1 | E20: =C20-D20 -> 849726.87 | F20: {=INDEX($F$27:$F$56,$A20)} -> 3673876 | G20: {=INDEX($J$27:$J$56,$A20)} -> 3363634.8 | H20: =F20-G20 -> 310241.17
A21: 20 | B21: {=INDEX($B$27:$B$56,$A21)} -> 4800000 | C21: {=INDEX($C$27:$C$56,$A21)} -> 18502021 | D21: {=INDEX($G$27:$G$56,$A21)} -> 16210098 | E21: =C21-D21 -> 2291923.7 | F21: {=INDEX($F$27:$F$56,$A21)} -> 5239845.2 | G21: {=INDEX($J$27:$J$56,$A21)} -> 4614541.7 | H21: =F21-G21 -> 625303.56
A22: 25 | B22: {=INDEX($B$27:$B$56,$A22)} -> 6000000 | C22: {=INDEX($C$27:$C$56,$A22)} -> 34402310 | D22: {=INDEX($G$27:$G$56,$A22)} -> 28909377 | E22: =C22-D22 -> 5492932.6 | F22: {=INDEX($F$27:$F$56,$A22)} -> 7192119.2 | G22: {=INDEX($J$27:$J$56,$A22)} -> 6072254.2 | H22: =F22-G22 -> 1119865
A23: 30 | B23: {=INDEX($B$27:$B$56,$A23)} -> 7200000 | C23: {=INDEX($C$27:$C$56,$A23)} -> 62581944 | D23: {=INDEX($G$27:$G$56,$A23)} -> 50328020 | E23: =C23-D23 -> 12253924 | F23: {=INDEX($F$27:$F$56,$A23)} -> 9693551.2 | G23: {=INDEX($J$27:$J$56,$A23)} -> 7826710.4 | H23: =F23-G23 -> 1866840.7
A25: YEARLY EXPENSE-RATIO IMPACT SCHEDULE
A26: Year | B26: Total Invested | C26: Direct Value Before Tax | D26: Direct LTCG Tax | E26: Direct Post-Tax Value | F26: Direct Post-Tax Real | G26: Regular Value Before Tax | H26: Regular LTCG Tax | I26: Regular Post-Tax Value | J26: Regular Post-Tax Real | K26: Pre-Tax Wealth Lost | L26: Real Wealth Lost
A27: =ROW()-26 -> 1 | B27: =$B$5+$B$6*12*A27 -> 240000 | C27: =$B$5*(1+($B$7-$B$8)/1200)^(12*A27)+FV(($B$7-$B$8)/1200,12*A27,-$B$6,0,0) -> 253062.95 | D27: =MAX(0,C27-B27-$B$13)*$B$12/100 -> 0 | E27: =C27-D27 -> 253062.95 | F27: =E27/(1+$B$11/100)^A27 -> 238738.63 | G27: =$B$5*(1+($B$7-$B$9)/1200)^(12*A27)+FV(($B$7-$B$9)/1200,12*A27,-$B$6,0,0) -> 251893.6 | H27: =MAX(0,G27-B27-$B$13)*$B$12/100 -> 0 | I27: =G27-H27 -> 251893.6 | J27: =I27/(1+$B$11/100)^A27 -> 237635.47 | K27: =C27-G27 -> 1169.3446 | L27: =F27-J27 -> 1103.1553
A28: =ROW()-26 -> 2 | B28: =$B$5+$B$6*12*A28 -> 480000 | C28: =$B$5*(1+($B$7-$B$8)/1200)^(12*A28)+FV(($B$7-$B$8)/1200,12*A28,-$B$6,0,0) -> 536812.13 | D28: =MAX(0,C28-B28-$B$13)*$B$12/100 -> 0 | E28: =C28-D28 -> 536812.13 | F28: =E28/(1+$B$11/100)^A28 -> 477760.89 | G28: =$B$5*(1+($B$7-$B$9)/1200)^(12*A28)+FV(($B$7-$B$9)/1200,12*A28,-$B$6,0,0) -> 531546.75 | H28: =MAX(0,G28-B28-$B$13)*$B$12/100 -> 0 | I28: =G28-H28 -> 531546.75 | J28: =I28/(1+$B$11/100)^A28 -> 473074.71 | K28: =C28-G28 -> 5265.3881 | L28: =F28-J28 -> 4686.1766
A29: =ROW()-26 -> 3 | B29: =$B$5+$B$6*12*A29 -> 720000 | C29: =$B$5*(1+($B$7-$B$8)/1200)^(12*A29)+FV(($B$7-$B$8)/1200,12*A29,-$B$6,0,0) -> 854968.56 | D29: =MAX(0,C29-B29-$B$13)*$B$12/100 -> 1246.0698 | E29: =C29-D29 -> 853722.49 | F29: =E29/(1+$B$11/100)^A29 -> 716801.86 | G29: =$B$5*(1+($B$7-$B$9)/1200)^(12*A29)+FV(($B$7-$B$9)/1200,12*A29,-$B$6,0,0) -> 842018.63 | H29: =MAX(0,G29-B29-$B$13)*$B$12/100 -> 0 | I29: =G29-H29 -> 842018.63 | J29: =I29/(1+$B$11/100)^A29 -> 706975.08 | K29: =C29-G29 -> 12949.926 | L29: =F29-J29 -> 9826.7833
A30: =ROW()-26 -> 4 | B30: =$B$5+$B$6*12*A30 -> 960000 | C30: =$B$5*(1+($B$7-$B$8)/1200)^(12*A30)+FV(($B$7-$B$8)/1200,12*A30,-$B$6,0,0) -> 1211704.4 | D30: =MAX(0,C30-B30-$B$13)*$B$12/100 -> 15838.052 | E30: =C30-D30 -> 1195866.4 | F30: =E30/(1+$B$11/100)^A30 -> 947238.17 | G30: =$B$5*(1+($B$7-$B$9)/1200)^(12*A30)+FV(($B$7-$B$9)/1200,12*A30,-$B$6,0,0) -> 1186705.6 | H30: =MAX(0,G30-B30-$B$13)*$B$12/100 -> 12713.199 | I30: =G30-H30 -> 1173992.4 | J30: =I30/(1+$B$11/100)^A30 -> 929911.94 | K30: =C30-G30 -> 24998.825 | L30: =F30-J30 -> 17326.234
A31: =ROW()-26 -> 5 | B31: =$B$5+$B$6*12*A31 -> 1200000 | C31: =$B$5*(1+($B$7-$B$8)/1200)^(12*A31)+FV(($B$7-$B$8)/1200,12*A31,-$B$6,0,0) -> 1611697.8 | D31: =MAX(0,C31-B31-$B$13)*$B$12/100 -> 35837.228 | E31: =C31-D31 -> 1575860.6 | F31: =E31/(1+$B$11/100)^A31 -> 1177574.7 | G31: =$B$5*(1+($B$7-$B$9)/1200)^(12*A31)+FV(($B$7-$B$9)/1200,12*A31,-$B$6,0,0) -> 1569378.2 | H31: =MAX(0,G31-B31-$B$13)*$B$12/100 -> 30547.281 | I31: =G31-H31 -> 1538831 | J31: =I31/(1+$B$11/100)^A31 -> 1149904 | K31: =C31-G31 -> 42319.582 | L31: =F31-J31 -> 27670.697
A32: =ROW()-26 -> 6 | B32: =$B$5+$B$6*12*A32 -> 1440000 | C32: =$B$5*(1+($B$7-$B$8)/1200)^(12*A32)+FV(($B$7-$B$8)/1200,12*A32,-$B$6,0,0) -> 2060194.2 | D32: =MAX(0,C32-B32-$B$13)*$B$12/100 -> 61899.271 | E32: =C32-D32 -> 1998294.9 | F32: =E32/(1+$B$11/100)^A32 -> 1408719.1 | G32: =$B$5*(1+($B$7-$B$9)/1200)^(12*A32)+FV(($B$7-$B$9)/1200,12*A32,-$B$6,0,0) -> 1994222.7 | H32: =MAX(0,G32-B32-$B$13)*$B$12/100 -> 53652.843 | I32: =G32-H32 -> 1940569.9 | J32: =I32/(1+$B$11/100)^A32 -> 1368025.2 | K32: =C32-G32 -> 65971.425 | L32: =F32-J32 -> 40693.845
A33: =ROW()-26 -> 7 | B33: =$B$5+$B$6*12*A33 -> 1680000 | C33: =$B$5*(1+($B$7-$B$8)/1200)^(12*A33)+FV(($B$7-$B$8)/1200,12*A33,-$B$6,0,0) -> 2563074.9 | D33: =MAX(0,C33-B33-$B$13)*$B$12/100 -> 94759.359 | E33: =C33-D33 -> 2468315.5 | F33: =E33/(1+$B$11/100)^A33 -> 1641570.8 | G33: =$B$5*(1+($B$7-$B$9)/1200)^(12*A33)+FV(($B$7-$B$9)/1200,12*A33,-$B$6,0,0) -> 2465886.6 | H33: =MAX(0,G33-B33-$B$13)*$B$12/100 -> 82610.821 | I33: =G33-H33 -> 2383275.7 | J33: =I33/(1+$B$11/100)^A33 -> 1585014.5 | K33: =C33-G33 -> 97188.303 | L33: =F33-J33 -> 56556.301
A34: =ROW()-26 -> 8 | B34: =$B$5+$B$6*12*A34 -> 1920000 | C34: =$B$5*(1+($B$7-$B$8)/1200)^(12*A34)+FV(($B$7-$B$8)/1200,12*A34,-$B$6,0,0) -> 3126934.6 | D34: =MAX(0,C34-B34-$B$13)*$B$12/100 -> 135241.82 | E34: =C34-D34 -> 2991692.7 | F34: =E34/(1+$B$11/100)^A34 -> 1877025 | G34: =$B$5*(1+($B$7-$B$9)/1200)^(12*A34)+FV(($B$7-$B$9)/1200,12*A34,-$B$6,0,0) -> 2989529.4 | H34: =MAX(0,G34-B34-$B$13)*$B$12/100 -> 118066.17 | I34: =G34-H34 -> 2871463.2 | J34: =I34/(1+$B$11/100)^A34 -> 1801591.5 | K34: =C34-G34 -> 137405.18 | L34: =F34-J34 -> 75433.494
A35: =ROW()-26 -> 9 | B35: =$B$5+$B$6*12*A35 -> 2160000 | C35: =$B$5*(1+($B$7-$B$8)/1200)^(12*A35)+FV(($B$7-$B$8)/1200,12*A35,-$B$6,0,0) -> 3759167.5 | D35: =MAX(0,C35-B35-$B$13)*$B$12/100 -> 184270.94 | E35: =C35-D35 -> 3574896.6 | F35: =E35/(1+$B$11/100)^A35 -> 2115975.8 | G35: =$B$5*(1+($B$7-$B$9)/1200)^(12*A35)+FV(($B$7-$B$9)/1200,12*A35,-$B$6,0,0) -> 3570879.4 | H35: =MAX(0,G35-B35-$B$13)*$B$12/100 -> 160734.93 | I35: =G35-H35 -> 3410144.5 | J35: =I35/(1+$B$11/100)^A35 -> 2018459.3 | K35: =C35-G35 -> 188288.05 | L35: =F35-J35 -> 97516.482
A36: =ROW()-26 -> 10 | B36: =$B$5+$B$6*12*A36 -> 2400000 | C36: =$B$5*(1+($B$7-$B$8)/1200)^(12*A36)+FV(($B$7-$B$8)/1200,12*A36,-$B$6,0,0) -> 4468064.6 | D36: =MAX(0,C36-B36-$B$13)*$B$12/100 -> 242883.07 | E36: =C36-D36 -> 4225181.5 | F36: =E36/(1+$B$11/100)^A36 -> 2359319.3 | G36: =$B$5*(1+($B$7-$B$9)/1200)^(12*A36)+FV(($B$7-$B$9)/1200,12*A36,-$B$6,0,0) -> 4216296.3 | H36: =MAX(0,G36-B36-$B$13)*$B$12/100 -> 211412.03 | I36: =G36-H36 -> 4004884.2 | J36: =I36/(1+$B$11/100)^A36 -> 2236306.4 | K36: =C36-G36 -> 251768.28 | L36: =F36-J36 -> 123012.83
A37: =ROW()-26 -> 11 | B37: =$B$5+$B$6*12*A37 -> 2640000 | C37: =$B$5*(1+($B$7-$B$8)/1200)^(12*A37)+FV(($B$7-$B$8)/1200,12*A37,-$B$6,0,0) -> 5262922 | D37: =MAX(0,C37-B37-$B$13)*$B$12/100 -> 312240.25 | E37: =C37-D37 -> 4950681.8 | F37: =E37/(1+$B$11/100)^A37 -> 2607957.4 | G37: =$B$5*(1+($B$7-$B$9)/1200)^(12*A37)+FV(($B$7-$B$9)/1200,12*A37,-$B$6,0,0) -> 4932840.3 | H37: =MAX(0,G37-B37-$B$13)*$B$12/100 -> 270980.03 | I37: =G37-H37 -> 4661860.2 | J37: =I37/(1+$B$11/100)^A37 -> 2455809.8 | K37: =C37-G37 -> 330081.74 | L37: =F37-J37 -> 152147.57
A38: =ROW()-26 -> 12 | B38: =$B$5+$B$6*12*A38 -> 2880000 | C38: =$B$5*(1+($B$7-$B$8)/1200)^(12*A38)+FV(($B$7-$B$8)/1200,12*A38,-$B$6,0,0) -> 6154163.3 | D38: =MAX(0,C38-B38-$B$13)*$B$12/100 -> 393645.42 | E38: =C38-D38 -> 5760517.9 | F38: =E38/(1+$B$11/100)^A38 -> 2862800.9 | G38: =$B$5*(1+($B$7-$B$9)/1200)^(12*A38)+FV(($B$7-$B$9)/1200,12*A38,-$B$6,0,0) -> 5728349.9 | H38: =MAX(0,G38-B38-$B$13)*$B$12/100 -> 340418.74 | I38: =G38-H38 -> 5387931.2 | J38: =I38/(1+$B$11/100)^A38 -> 2677636.7 | K38: =C38-G38 -> 425813.45 | L38: =F38-J38 -> 185164.21
... A56: =ROW()-26 -> 30 | B56: =$B$5+$B$6*12*A56 -> 7200000 | C56: =$B$5*(1+($B$7-$B$8)/1200)^(12*A56)+FV(($B$7-$B$8)/1200,12*A56,-$B$6,0,0) -> 62581944 | D56: =MAX(0,C56-B56-$B$13)*$B$12/100 -> 6907118 | E56: =C56-D56 -> 55674826 | F56: =E56/(1+$B$11/100)^A56 -> 9693551.2 | G56: =$B$5*(1+($B$7-$B$9)/1200)^(12*A56)+FV(($B$7-$B$9)/1200,12*A56,-$B$6,0,0) -> 50328020 | H56: =MAX(0,G56-B56-$B$13)*$B$12/100 -> 5375377.5 | I56: =G56-H56 -> 44952642 | J56: =I56/(1+$B$11/100)^A56 -> 7826710.4 | K56: =C56-G56 -> 12253924 | L56: =F56-J56 -> 1866840.7
A59: ASSUMPTIONS & LIMITATIONS
A60: 1. Net return is modeled as gross annual return minus the annual expense ratio, compounded monthly. Actual NAVs deduct expenses daily and realized returns vary.
A61: 2. Direct and regular plans are assumed to hold the same portfolio. Distributor advice, service quality, exit loads, tracking differences, cess, surcharge, and tax-lot timing are excluded.
A62: 3. The tax estimate assumes one full year-end redemption and qualifying long-term gains above the exemption; recent SIP instalments may not qualify as long term.

Sheet Loan Prepayment
A1: HOME-LOAN PREPAYMENT & RATE-CHANGE SCENARIO CALCULATOR
A2: Compare a normal loan, multiple lump sums, monthly extra payments, a mid-term rate change, and their combined effect.
A4: LOAN & PREPAYMENT INPUTS | D4: NORMAL LOAN SUMMARY | G4: SELECTED SCENARIO SUMMARY
A5: Loan Amount (₹) | B5: 10000000 | D5: Monthly EMI | E5: =-PMT($B$6/1200,$B$7*12,$B$5) -> 80559.319 | G5: Chosen Scenario | H5: =$H$13 -> Combination of All
